Workbook

Sheet Task Agreement Form
A1: FACULTY OF EDUCATION - TASK AGREEMENT FORM (As for approval during Faculty Management Committee meeting of 12 September 2024)
A4: Lecturer: | B4: Byron Bunt | C4: Staff number: | D4: 20172672
A5: Post title (example: Snr Lecturer) | B5: Associate Professor | C5: Race (for equity purposes): | D5: White
A6: Qualification: | B6: PhD | C6: Gender: | D6: Male
A7: Year to which the task agreement applies: | B7: 2025 | C7: School: | D7: SCSSE
A8: Mentor: | B8: Prof. Elsa Mentz | C8: Research entity: | D8: SDL
A9: GENERAL INSTRUCTIONS: *Please also read all the instructions marked in yellow. *Where you fill in the hours in Column D, please use a comma for decimals. (Ex. 30min are typed as 0,5) - numbers only in column D please! *Column E automatically calculates the percentage (%) of the task against the total number of hours added. *Please do not under any circumstances copy & paste or try to add or delete lines - the document has a lot of formulas. *Should the number of hours (Norm) be exceeded, assistance will be provided and needs to be managed by the lecturer. *ADDENDUM B CONTACT DELIVERY -Where "Lectures per week CONTACT" is required, please fill in the number of periods/hours per week (add up all the session times). -Delivery of a module is calculated against the standard of 10 weeks per semester to allow for consistency across the faculty. -Contact time (number of lectures) for respective modules are calculated as follows: 8 credit = 1 period/hour per week, 12 credit (generic module) = 1 period/hour per week, 12 credit (methodology / core module) = 2 periods/hours per week, 16 credit = 2 periods/hours per week. DISTANCE DELIVERY -Number of hours total contact time required for respective distance modules are calculated as follows: 8 credit module = 6 hours (minimum of 3 hours synchronous contact time) per semester, 12 credit module = 9 hours (minimum of 4.5 hours synchronous contact time) per semester, 16 credit module = 12 hours (minimum of 6 hours synchronous contact time) per semester, 20-24 credit module = 16 hours (minimum of 8 hours synchronous contact time) per semester.
A10: Norm = 1728 hours
A11: ITEM | B11: CALCULATION AND DETAILS | D11: NUMBER OF HOURS | E11: %
A12: SECTION 1 DIY Performance Agreement KPA: Personal Research, Innovation and/or Creative Outputs
A13: Use Addendum A as guideline
A14: 1.1 Subsidy-bearing articles | B14: Only articles to be submitted in the following year, calculated as follows: Single author: 150 hours for ISI journal and 100 hours for DHE journal. One of two authors: 75 hours for ISI journal and 50 hours for DHE journal. One of three authors: 50 hours for ISI journal and 35 hours for DHE journal.
B15: Provisional title, authors, journal, planned submission date | C15: CESM code | D15: Hours
B16: Level Up Learning: Enhancing Self-Directed Learning in Computer Applications Technology with Classcraft | D16: 50 | E16: =((D16*100)/$D$384) -> 2.3041581
B17: Game-Based Learning in History Education: Insights from “Dogs of War” | D17: 75 | E17: =((D17*100)/$D$384) -> 3.4562371
B18: Revitalizing Classrooms: Integrating Indigenous Knowledge and Ubuntu in Social Sciences Education | D18: 50 | E18: =((D18*100)/$D$384) -> 2.3041581
D19: 0 | E19: =((D19*100)/$D$384) -> 0
D20: 0 | E20: =((D20*100)/$D$384) -> 0
D21: 0 | E21: =((D21*100)/$D$384) -> 0
D22: 0 | E22: =((D22*100)/$D$384) -> 0
D23: 0 | E23: =((D23*100)/$D$384) -> 0
D24: 0 | E24: =((D24*100)/$D$384) -> 0
A25: 1.2 Projects within research entity | B25: Entity leader (niche/niche 0): 100 hours NB! List below.
D26: 0 | E26: =((D26*100)/$D$384) -> 0
B27: Research project leader (no funding = 50 hours; under R20 000 = 80 hours; R20 001—R50 000 = 100 hours; R50 001—R100 000 = 150 hours; R100 001—R500 000 = 200 hours; more than R500 001 = 300 hours). NB! List research projects below.
B28: Prosper GREAT project | D28: 50 | E28: =((D28*100)/$D$384) -> 2.3041581
D29: 0 | E29: =((D29*100)/$D$384) -> 0
D30: 0 | E30: =((D30*100)/$D$384) -> 0
B31: Research project participant (1 TO 5 PARTICIPANTS) (no funding = 10 hours; under R20 000 = 30 hours; R20 001—R50 000 = 60 hours; R50 001—R100 000 = 80 hours; R100 001—R500 000 = 100 hours; more than R500 000 = 200 hours). NB! List details below.
B32: Citesaga project, Renewable Rangers project | D32: 20 | E32: =((D32*100)/$D$384) -> 0.92166323
B33: Research project participant (MORE THAN 5 PARTICIPANTS) (no funding = 8 hours; under R20 000 = 20 hours; R20 001—R50 000 = 30 hours; R50 001—R100 000 = 60 hours; R100 001—R500 000 = 80 hours; more than R500 000 = 120 hours). NB! List details below.
D34: 0 | E34: =((D34*100)/$D$384) -> 0
B35: Papers to be presented Maximum 45 hours per year consisting of 15 hours per conference. NB! List details below.
B36: ECGBL | D36: 15 | E36: =((D36*100)/$D$384) -> 0.69124743
B37: SDL | D37: 15 | E37: =((D37*100)/$D$384) -> 0.69124743
D38: 0 | E38: =((D38*100)/$D$384) -> 0
A39: 1.3 Other research outputs | B39: Selection and examination of articles and projects Maximum of 5 hours per item up to a maximum of 20 hours per year (or 4 items). NB! List details below.
D40: 0 | E40: =((D40*100)/$D$384) -> 0
D41: 0 | E41: =((D41*100)/$D$384) -> 0
D42: 0 | E42: =((D42*100)/$D$384) -> 0
...

Sheet AddendumA - Module & CESM codes
A1: CODES FOR SUPERVISION AND RESEARCH
A3: 2.1 SUPERVISION | H3: CESM codes for research discipline (must be the 6-figure code)
A4: Descriptive Name / | B4: Curriculum Abbreviation / Module kode | C4: Credits / Krediete | D4: Campuses / | H4: 1.1 CESM codes
A5: Beskrywende naam | D5: Kampusse
D6: P | E6: V | F6: M
A7: Curriculum Studies | B7: CRSE 871 | C7: 180 | D7: √ | E7: √
A8: Kurrikulumstudies
A9: Physical Science Education with Natural Science Education | B9: PHSE 871 | C9: 180 | D9: √
A10: Fisiese Wetenskaponderwys met Natuurwetenskaponderwys
A11: Educational Management and Leadership | B11: EDMA 871 | C11: 180 | D11: √ | E11: √ | F11: √
A12: Onderwysbestuur en Leierskap
A13: Education Law | B13: EDLW 871 | C13: 180 | D13: √ | E13: √
A14: Onderwysreg
A15: Educational Psychology | B15: EPSY 871 | C15: 180 | D15: √
A16: Opvoedkundige Sielkunde
A17: International and Comparative Education | B17: CMPE 871 | C17: 180 | D17: √
A18: Internasionale en Vergelykende Opvoedkunde
A19: Mathematics Education | B19: MATE 871 | C19: 180 | D19: √
A20: Wiskunde-onderwys
A21: Special Needs Education | B21: SPNE 871 | C21: 180 | D21: √ | E21: √
A22: Onderwys vir Spesiale Behoeftes
A23: Philosophy of Education | B23: PHIE 871 | C23: 180 | D23: √
A24: Filosofie van Opvoedkunde
A25: Physical Education | B25: MOVE 871 | C25: 180 | D25: √
A26: Liggaamlike Opvoeding
A27: Information Technology Education* | B27: CSIE 871 | C27: 240 | D27: √
A28: Inligtingstegnologie-onderwys*
A29: Maths/Science Education | B29: SEDM 871 | C29: 180 | F29: √
A30: Wiskunde/Wetenskap Onderwys
A31: Language Education / | B31: EDSL 871 | C31: 180 | D31: √ | E31: √ | F31: √
A32: Taalonderwys
A34: Descriptive Name / | B34: Curriculum Abbreviation / Module kode | C34: Credits / Krediete | D34: Campuses /
A35: Beskrywende naam | D35: Kampusse
D36: P | E36: V | F36: M
A37: Natural Science Education | B37: PHSE 971 | C37: 360 | D37: √ | F37: √
A38: Fisiese Natuurwetenskaponderwys
A39: Educational Management | B39: EDMA 971 | C39: 360 | D39: √ | E39: √ | F39: √
A40: Onderwysbestuur
A41: Education Law | B41: EDLW 971 | C41: 360 | D41: √ | E41: √ | F41: √
A42: Onderwysreg
...

Sheet AddendumB - Section 2 calculati
A1: *NB! PLEASE PAY CAREFUL ATTENTION TO THE INSTRUCTIONS ON THE TASK AGREEMENT FORM
A2: 1st year modules: BEd and Diploma | C2: 2nd year modules: BEd and Diploma | E2: 3rd year modules: BEd and Diploma; All modules: AdvCert (ACT) | G2: 4th year modules: BEd; All modules: PGCE and AdvDip (ADE) | I2: BEd Hons (ONLY Contact, unless module is alligned on distance and NOT indicated under Section 2.7) | K2: MEd Structured (from 2025)
A3: MODULE CODE | C3: MODULE CODE | E3: MODULE CODE | F3: HISE 322 | G3: MODULE CODE | H3: HISE 411 | I3: MODULE CODE | K3: MODULE CODE
A4: Number of students CONTACT (a) | B4: 0 | C4: Number of students CONTACT (a) | D4: 0 | E4: Number of students CONTACT (a) | F4: 40 | G4: Number of students CONTACT (a) | H4: 35 | I4: Number of students CONTACT (a) | J4: 0 | K4: Number of students CONTACT (a) | L4: 0
A5: Number of lectures per week CONTACT that you present (b) | B5: 0 | C5: Number of lectures per week CONTACT that you present (b) | D5: 0 | E5: Number of lectures per week CONTACT that you present (b) | F5: 2 | G5: Number of lectures per week CONTACT that you present (b) | H5: 2 | I5: Number of lectures per week CONTACT that you present (b) | J5: 0 | K5: Number of lectures per week CONTACT that you present (b) | L5: 0
A6: Number of weeks CONTACT that you present lectures (c) | B6: 0 | C6: Number of weeks CONTACT that you present lectures (c) | D6: 0 | E6: Number of weeks CONTACT that you present lectures (c) | F6: 10 | G6: Number of weeks CONTACT that you present lectures (c) | H6: 10 | I6: Number of weeks CONTACT that you present lectures (c) | J6: 0 | K6: Number of weeks CONTACT that you present lectures (c) | L6: 0
A7: Number of students DISTANCE (d) | B7: 0 | C7: Number of students DISTANCE (d) | D7: 0 | E7: Number of students DISTANCE (d) | F7: 0 | G7: Number of students DISTANCE (d) | H7: 0 | I7: Number of students DISTANCE (d) | J7: 0 | K7: Number of students DISTANCE (d) | L7: 0
A8: Total number of hours contact sessions DISTANCE (e) | B8: 0 | C8: Total number of hours contact sessions DISTANCE (e) | D8: 0 | E8: Total number of hours contact sessions DISTANCE (e) | F8: 0 | G8: Total number of hours contact sessions DISTANCE (e) | H8: 0 | I8: Total number of hours contact sessions DISTANCE (e) | J8: 0 | K8: Total number of hours contact sessions DISTANCE (e) | L8: 0
A9: Number of lecturers presenting (shared) module on same campus during the same 'weeks CONTACT' indicated (change to 2 or 3 if applicable) | B9: 1 | C9: Number of lecturers presenting (shared) module on same campus during the same 'weeks CONTACT' indicated (change to 2 or 3 if applicable) | D9: 1 | E9: Number of lecturers presenting (shared) module on same campus during the same 'weeks CONTACT' indicated (change to 2 or 3 if applicable) | F9: 1 | G9: Number of lecturers presenting (shared) module on same campus during the same 'weeks CONTACT' indicated (change to 2 or 3 if applicable) | H9: 1 | I9: Number of lecturers presenting (shared) module on same campus during the same 'weeks CONTACT' indicated (change to 2 or 3 if applicable) | J9: 1 | K9: Number of lecturers presenting (shared) module on same campus during the same 'weeks CONTACT' indicated (change to 2 or 3 if applicable) | L9: 1
A10: Calculation of hours | B10: HOURS | C10: Calculation of hours | D10: HOURS | E10: Calculation of hours | F10: HOURS | G10: Calculation of hours | H10: HOURS | I10: Calculation of hours | J10: HOURS | K10: Calculation of hours | L10: HOURS
A11: Number of lectures | B11: =(B5*B6)+B8 -> 0 | C11: Number of lectures | D11: =(D5*D6)+D8 -> 0 | E11: Number of lectures | F11: =(F5*F6)+F8 -> 20 | G11: Number of lectures | H11: =(H5*H6)+H8 -> 20 | I11: Number of lectures | J11: =(J5*J6)+J8 -> 0 | K11: Number of lectures | L11: =(L5*L6)+L8 -> 0
A12: Preparation (contact and distance lecturer) | B12: =(B5*B6)+B8 -> 0 | C12: Preparation (contact and distance lecturer) | D12: =(D5*D6)+D8 -> 0 | E12: Preparation (contact and distance lecturer) | F12: =(F5*F6)+F8 -> 20 | G12: Preparation (contact and distance lecturer) | H12: =(H5*H6)+H8 -> 20 | I12: Preparation (contact and distance lecturer) | J12: =((J5*J6)+J8)*1.5 -> 0 | K12: Preparation (contact and distance lecturer) | L12: =((L5*L6)+L8)*2 -> 0
A13: Support to students | B13: =(((B4*0.08)*(B6/10))+(B7*0.16))/B9 -> 0 | C13: Support to students | D13: =(((D4*0.08)*(D6/10))+(D7*0.16))/D9 -> 0 | E13: Support to students | F13: =(((F4*0.08)*(F6/10))+(F7*0.16))/F9 -> 3.2 | G13: Support to students | H13: =((H4*0.08)+(H7*0.16))/H9 -> 2.8 | I13: Support to students | J13: =(((J4*0.08)*(J6/10))+(J7*0.16))/J9 -> 0 | K13: Support to students | L13: =(((L4*0.08)*(L6/10))+(L7*0.16))/L9 -> 0
A14: Exam question papers + memos (12—16 hours per question paper divided by Number of lecturers drafting paper) ONE LANGUAGE … question papers @ … hours per question paper | B14: 0 | C14: Exam question papers + memos (12—16 hours per question paper divided by Number of lecturers drafting paper) ONE LANGUAGE … question papers @ … hours per question paper | D14: 0 | E14: Exam question papers + memos (12—16 hours per question paper divided by Number of lecturers drafting paper) ONE LANGUAGE … question papers @ … hours per question paper | F14: 12 | G14: Exam question papers + memos (12—16 hours per question paper divided by Number of lecturers drafting paper) ONE LANGUAGE … question papers @ … hours per question paper | H14: 12 | I14: Exam question papers + memos (12—16 hours per question paper divided by Number of lecturers drafting paper) ONE LANGUAGE … question papers @ … hours per question paper | J14: 0 | K14: Exam question papers + memos (12—16 hours per question paper divided by Number of lecturers drafting paper) ONE LANGUAGE … question papers @ … hours per question paper | L14: 0
A15: Exam question papers + memos (2—5 hours per question paper divided by Number of lecturers drafting paper) TRANSLATION … question papers @ … hours per question paper | B15: 0 | C15: Exam question papers + memos (2—5 hours per question paper divided by Number of lecturers drafting paper) TRANSLATION … question papers @ … hours per question paper | D15: 0 | E15: Exam question papers + memos (2—5 hours per question paper divided by Number of lecturers drafting paper) TRANSLATION … question papers @ … hours per question paper | F15: 2 | G15: Exam question papers + memos (2—5 hours per question paper divided by Number of lecturers drafting paper) TRANSLATION … question papers @ … hours per question paper | H15: 2 | I15: Exam question papers + memos (2—5 hours per question paper divided by Number of lecturers drafting paper) TRANSLATION … question papers @ … hours per question paper | J15: 0 | K15: Exam question papers + memos (2—5 hours per question paper divided by Number of lecturers drafting paper) TRANSLATION … question papers @ … hours per question paper | L15: 0
A16: Assessment (ONLY CONTACT) | B16: =(B4*(B6/10))/B9 -> 0 | C16: Assessment (ONLY CONTACT) | D16: =(D4*(D6/10))/D9 -> 0 | E16: Assessment (ONLY CONTACT) | F16: =(F4*(F6/10))/F9 -> 40 | G16: Assessment (ONLY CONTACT) | H16: =(H4*(H6/10))/H9 -> 35 | I16: Assessment (ONLY CONTACT) | J16: =(J4*(J6/10))/J9 -> 0 | K16: Assessment (ONLY CONTACT) | L16: =(L4*(L6/10))/L9 -> 0
A17: Assessment (additional) Reasons: | B17: 0 | C17: Assessment (additional) Reasons: | D17: 0 | E17: Assessment (additional) Reasons: | F17: 0 | G17: Assessment (additional) Reasons: | H17: 0 | I17: Assessment (additional) Reasons: | J17: 0 | K17: Assessment (additional) Reasons: | L17: 0
A18: Practicals for Natural Science, Physical Science, Life Science & Geography (@ 0,5 hours per student divided by Number of lecturers presenting practical) (Number of contact students + number of distance students) /2 | B18: 0 | C18: Practicals for Natural Science, Physical Science, Life Science & Geography (@ 0,5 hours per student divided by Number of lecturers presenting practical) (Number of contact students + number of distance students) /2 | D18: 0 | E18: Practicals for Natural Science, Physical Science, Life Science & Geography (@ 0,5 hours per student divided by Number of lecturers presenting practical) (Number of contact students + number of distance students) /2 | F18: 0 | G18: Practicals for Natural Science, Physical Science, Life Science & Geography (@ 0,5 hours per student divided by Number of lecturers presenting practical) (Number of contact students + number of distance students) /2 | H18: 0 | I18: Practicals for Natural Science, Physical Science, Life Science & Geography (@ 0,5 hours per student divided by Number of lecturers presenting practical) (Number of contact students + number of distance students) /2 | J18: 0 | K18: Practicals for Natural Science, Physical Science, Life Science & Geography (@ 0,5 hours per student divided by Number of lecturers presenting practical) (Number of contact students + number of distance students) /2 | L18: 0
A19: Teaching administration | B19: =(B6+B8)/B9 -> 0 | C19: Teaching administration | D19: =(D6+D8)/D9 -> 0 | E19: Teaching administration | F19: =(F6+F8)/F9 -> 10 | G19: Teaching administration | H19: =(H6+H8)/H9 -> 10 | I19: Teaching administration | J19: =(J6+J8)/J9 -> 0 | K19: Teaching administration | L19: =(L6+L8)/L9 -> 0
A20: Total | B20: =SUM(B11:B19) -> 0 | C20: Total | D20: =SUM(D11:D19) -> 0 | E20: Total | F20: =SUM(F11:F19) -> 107.2 | G20: Total | H20: =SUM(H11:H19) -> 101.8 | I20: Total | J20: =SUM(J11:J19) -> 0 | K20: Total | L20: =SUM(L11:L19) -> 0
A21: * Assessment (distance) is included under marking quota on task time form | C21: * Assessment (distance) is included under marking quota on task time form | E21: * Assessment (distance) is included under marking quota on task time form | G21: * Assessment (distance) is included under marking quota on task time form | I21: * Assessment (distance) is included under marking quota on task time form | K21: * Assessment (distance) is included under marking quota on task time form
A22: Year level adjustment (none) | B22: =B20 -> 0 | C22: Year level adjustment | D22: =D20*1.05 -> 0 | E22: Year level adjustment | F22: =F20*1.1 -> 117.92 | G22: Year level adjustment | H22: =H20*1.15 -> 117.07 | I22: Year level adjustment | J22: =J20*1.2 -> 0 | K22: Year level adjustment | L22: =L20*1.25 -> 0
A24: MODULE CODE | C24: MODULE CODE | E24: MODULE CODE | G24: MODULE CODE | I24: MODULE CODE | K24: MODULE CODE
A25: Number of students CONTACT (a) | B25: 0 | C25: Number of students CONTACT (a) | D25: 0 | E25: Number of students CONTACT (a) | F25: 0 | G25: Number of students CONTACT (a) | H25: 0 | I25: Number of students CONTACT (a) | J25: 0 | K25: Number of students CONTACT (a) | L25: 0
A26: Number of lectures per week CONTACT that you present (b) | B26: 0 | C26: Number of lectures per week CONTACT that you present (b) | D26: 0 | E26: Number of lectures per week CONTACT that you present (b) | F26: 0 | G26: Number of lectures per week CONTACT that you present (b) | H26: 0 | I26: Number of lectures per week CONTACT that you present (b) | J26: 0 | K26: Number of lectures per week CONTACT that you present (b) | L26: 0
A27: Number of weeks CONTACT that you present lectures (c) | B27: 0 | C27: Number of weeks CONTACT that you present lectures (c) | D27: 0 | E27: Number of weeks CONTACT that you present lectures (c) | F27: 0 | G27: Number of weeks CONTACT that you present lectures (c) | H27: 0 | I27: Number of weeks CONTACT that you present lectures (c) | J27: 0 | K27: Number of weeks CONTACT that you present lectures (c) | L27: 0
A28: Number of students DISTANCE (d) | B28: 0 | C28: Number of students DISTANCE (d) | D28: 0 | E28: Number of students DISTANCE (d) | F28: 0 | G28: Number of students DISTANCE (d) | H28: 0 | I28: Number of students DISTANCE (d) | J28: 0 | K28: Number of students DISTANCE (d) | L28: 0
A29: Total number of hours contact sessions DISTANCE (e) | B29: 0 | C29: Total number of hours contact sessions DISTANCE (e) | D29: 0 | E29: Total number of hours contact sessions DISTANCE (e) | F29: 0 | G29: Total number of hours contact sessions DISTANCE (e) | H29: 0 | I29: Total number of hours contact sessions DISTANCE (e) | J29: 0 | K29: Total number of hours contact sessions DISTANCE (e) | L29: 0
A30: Number of lecturers presenting (shared) module on same campus during the same 'weeks CONTACT' indicated (change to 2 or 3 if applicable) | B30: 1 | C30: Number of lecturers presenting (shared) module on same campus during the same 'weeks CONTACT' indicated (change to 2 or 3 if applicable) | D30: 1 | E30: Number of lecturers presenting (shared) module on same campus during the same 'weeks CONTACT' indicated (change to 2 or 3 if applicable) | F30: 1 | G30: Number of lecturers presenting (shared) module on same campus during the same 'weeks CONTACT' indicated (change to 2 or 3 if applicable) | H30: 1 | I30: Number of lecturers presenting (shared) module on same campus during the same 'weeks CONTACT' indicated (change to 2 or 3 if applicable) | J30: 1 | K30: Number of lecturers presenting (shared) module on same campus during the same 'weeks CONTACT' indicated (change to 2 or 3 if applicable) | L30: 1
A31: Calculation of hours | B31: HOURS | C31: Calculation of hours | D31: HOURS | E31: Calculation of hours | F31: HOURS | G31: Calculation of hours | H31: HOURS | I31: Calculation of hours | J31: HOURS | K31: Calculation of hours | L31: HOURS
A32: Number of lectures | B32: =(B26*B27)+B29 -> 0 | C32: Number of lectures | D32: =(D26*D27)+D29 -> 0 | E32: Number of lectures | F32: =(F26*F27)+F29 -> 0 | G32: Number of lectures | H32: =(H26*H27)+H29 -> 0 | I32: Number of lectures | J32: =(J26*J27)+J29 -> 0 | K32: Number of lectures | L32: =(L26*L27)+L29 -> 0
A33: Preparation (contact and distance lecturer) | B33: =(B26*B27)+B29 -> 0 | C33: Preparation (contact and distance lecturer) | D33: =(D26*D27)+D29 -> 0 | E33: Preparation (contact and distance lecturer) | F33: =(F26*F27)+F29 -> 0 | G33: Preparation (contact and distance lecturer) | H33: =(H26*H27)+H29 -> 0 | I33: Preparation (contact and distance lecturer) | J33: =((J26*J27)+J29)*1.5 -> 0 | K33: Preparation (contact and distance lecturer) | L33: =((L26*L27)+L29)*2 -> 0
A34: Support to students | B34: =(((B25*0.08)*(B27/10))+(B28*0.16))/B30 -> 0 | C34: Support to students | D34: =(((D25*0.08)*(D27/10))+(D28*0.16))/D30 -> 0 | E34: Support to students | F34: =(((F25*0.08)*(F27/10))+(F28*0.16))/F30 -> 0 | G34: Support to students | H34: =((H25*0.08)+(H28*0.16))/H30 -> 0 | I34: Support to students | J34: =(((J25*0.08)*(J27/10))+(J28*0.16))/J30 -> 0 | K34: Support to students | L34: =(((L25*0.08)*(L27/10))+(L28*0.16))/L30 -> 0
A35: Exam question papers + memos (12—16 hours per question paper divided by Number of lecturers drafting paper) ONE LANGUAGE … question papers @ … hours per question paper | B35: 0 | C35: Exam question papers + memos (12—16 hours per question paper divided by Number of lecturers drafting paper) ONE LANGUAGE … question papers @ … hours per question paper | D35: 0 | E35: Exam question papers + memos (12—16 hours per question paper divided by Number of lecturers drafting paper) ONE LANGUAGE … question papers @ … hours per question paper | F35: 0 | G35: Exam question papers + memos (12—16 hours per question paper divided by Number of lecturers drafting paper) ONE LANGUAGE … question papers @ … hours per question paper | H35: 0 | I35: Exam question papers + memos (12—16 hours per question paper divided by Number of lecturers drafting paper) ONE LANGUAGE … question papers @ … hours per question paper | J35: 0 | K35: Exam question papers + memos (12—16 hours per question paper divided by Number of lecturers drafting paper) ONE LANGUAGE … question papers @ … hours per question paper | L35: 0
A36: Exam question papers + memos (2—5 hours per question paper divided by Number of lecturers drafting paper) TRANSLATION … question papers @ … hours per question paper | B36: 0 | C36: Exam question papers + memos (2—5 hours per question paper divided by Number of lecturers drafting paper) TRANSLATION … question papers @ … hours per question paper | D36: 0 | E36: Exam question papers + memos (2—5 hours per question paper divided by Number of lecturers drafting paper) TRANSLATION … question papers @ … hours per question paper | F36: 0 | G36: Exam question papers + memos (2—5 hours per question paper divided by Number of lecturers drafting paper) TRANSLATION … question papers @ … hours per question paper | H36: 0 | I36: Exam question papers + memos (2—5 hours per question paper divided by Number of lecturers drafting paper) TRANSLATION … question papers @ … hours per question paper | J36: 0 | K36: Exam question papers + memos (2—5 hours per question paper divided by Number of lecturers drafting paper) TRANSLATION … question papers @ … hours per question paper | L36: 0
A37: Assessment (ONLY CONTACT) | B37: =(B25*(B27/10))/B30 -> 0 | C37: Assessment (ONLY CONTACT) | D37: =(D25*(D27/10))/D30 -> 0 | E37: Assessment (ONLY CONTACT) | F37: =(F25*(F27/10))/F30 -> 0 | G37: Assessment (ONLY CONTACT) | H37: =(H25*(H27/10))/H30 -> 0 | I37: Assessment (ONLY CONTACT) | J37: =(J25*(J27/10))/J30 -> 0 | K37: Assessment (ONLY CONTACT) | L37: =(L25*(L27/10))/L30 -> 0
A38: Assessment (additional) Reasons: | B38: 0 | C38: Assessment (additional) Reasons: | D38: 0 | E38: Assessment (additional) Reasons: | F38: 0 | G38: Assessment (additional) Reasons: | H38: 0 | I38: Assessment (additional) Reasons: | J38: 0 | K38: Assessment (additional) Reasons: | L38: 0
A39: Practicals for Natural Science, Physical Science, Life Science & Geography (@ 0,5 hours per student divided by Number of lecturers presenting practical) (Number of contact students + number of distance students) /2 | B39: 0 | C39: Practicals for Natural Science, Physical Science, Life Science & Geography (@ 0,5 hours per student divided by Number of lecturers presenting practical) (Number of contact students + number of distance students) /2 | D39: 0 | E39: Practicals for Natural Science, Physical Science, Life Science & Geography (@ 0,5 hours per student divided by Number of lecturers presenting practical) (Number of contact students + number of distance students) /2 | F39: 0 | G39: Practicals for Natural Science, Physical Science, Life Science & Geography (@ 0,5 hours per student divided by Number of lecturers presenting practical) (Number of contact students + number of distance students) /2 | H39: 0 | I39: Practicals for Natural Science, Physical Science, Life Science & Geography (@ 0,5 hours per student divided by Number of lecturers presenting practical) (Number of contact students + number of distance students) /2 | J39: 0 | K39: Practicals for Natural Science, Physical Science, Life Science & Geography (@ 0,5 hours per student divided by Number of lecturers presenting practical) (Number of contact students + number of distance students) /2 | L39: 0
A40: Teaching administration | B40: =(B27+B29)/B30 -> 0 | C40: Teaching administration | D40: =(D27+D29)/D30 -> 0 | E40: Teaching administration | F40: =(F27+F29)/F30 -> 0 | G40: Teaching administration | H40: =(H27+H29)/H30 -> 0 | I40: Teaching administration | J40: =(J27+J29)/J30 -> 0 | K40: Teaching administration | L40: =(L27+L29)/L30 -> 0
A41: Total | B41: =SUM(B32:B40) -> 0 | C41: Total | D41: =SUM(D32:D40) -> 0 | E41: Total | F41: =SUM(F32:F40) -> 0 | G41: Total | H41: =SUM(H32:H40) -> 0 | I41: Total | J41: =SUM(J32:J40) -> 0 | K41: Total | L41: =SUM(L32:L40) -> 0
...

Sheet DO NOT COMPLETE - HEMIS
A1: Hemis: | B1: ='Task Agreement Form'!$B$4 -> Byron Bunt | E1: ='Task Agreement Form'!D4 -> 20172672 | G1: 2025
A2: Faculty of Education | E2: ='Task Agreement Form'!$D$7 -> SCSSE
A3: Position: | D3: ='Task Agreement Form'!$B$5 -> Associate Professor
A4: Qualification: | C4: ='Task Agreement Form'!$B$6 -> PhD
A5: Race: | B5: ='Task Agreement Form'!$D$5 -> White | D5: Geslag: | E5: ='Task Agreement Form'!$D$6 -> Male
A7: Teaching and Learning | G7: Number of modules
B8: Module code | E8: Number of students | F8: % Time | H8: Total % time
B9: ='Task Agreement Form'!$B123 -> 0 | E9: ='Task Agreement Form'!C123 -> 0 | F9: ='Task Agreement Form'!$E123 -> 0 | H9: =IF(F9>0,F9+($F$148/$G$8),F9) -> 0
B10: ='Task Agreement Form'!$B124 -> 0 | E10: ='Task Agreement Form'!C124 -> 0 | F10: ='Task Agreement Form'!$E124 -> 0 | H10: =IF(F10>0,F10+($F$148/$G$8),F10) -> 0
B11: ='Task Agreement Form'!$B125 -> 0 | E11: ='Task Agreement Form'!C125 -> 0 | F11: ='Task Agreement Form'!$E125 -> 0 | H11: =IF(F11>0,F11+($F$148/$G$8),F11) -> 0
B12: ='Task Agreement Form'!$B126 -> 0 | E12: ='Task Agreement Form'!C126 -> 0 | F12: ='Task Agreement Form'!$E126 -> 0 | H12: =IF(F12>0,F12+($F$148/$G$8),F12) -> 0
B13: ='Task Agreement Form'!$B127 -> 0 | E13: ='Task Agreement Form'!C127 -> 0 | F13: ='Task Agreement Form'!$E127 -> 0 | H13: =IF(F13>0,F13+($F$148/$G$8),F13) -> 0
B14: ='Task Agreement Form'!$B128 -> 0 | E14: ='Task Agreement Form'!C128 -> 0 | F14: ='Task Agreement Form'!$E128 -> 0 | H14: =IF(F14>0,F14+($F$148/$G$8),F14) -> 0
B15: ='Task Agreement Form'!$B129 -> 0 | E15: ='Task Agreement Form'!C129 -> 0 | F15: ='Task Agreement Form'!$E129 -> 0 | H15: =IF(F15>0,F15+($F$148/$G$8),F15) -> 0
B16: ='Task Agreement Form'!$B130 -> 0 | E16: ='Task Agreement Form'!C130 -> 0 | F16: ='Task Agreement Form'!$E130 -> 0 | H16: =IF(F16>0,F16+($F$148/$G$8),F16) -> 0
B17: ='Task Agreement Form'!$B131 -> 0 | E17: ='Task Agreement Form'!C131 -> 0 | F17: ='Task Agreement Form'!$E131 -> 0 | H17: =IF(F17>0,F17+($F$148/$G$8),F17) -> 0
B18: ='Task Agreement Form'!$B132 -> 0 | E18: ='Task Agreement Form'!C132 -> 0 | F18: ='Task Agreement Form'!$E132 -> 0 | H18: =IF(F18>0,F18+($F$148/$G$8),F18) -> 0
B19: ='Task Agreement Form'!$B133 -> 0 | E19: ='Task Agreement Form'!C133 -> 0 | F19: ='Task Agreement Form'!$E133 -> 0 | H19: =IF(F19>0,F19+($F$148/$G$8),F19) -> 0
B20: ='Task Agreement Form'!$B134 -> 0 | E20: ='Task Agreement Form'!C134 -> 0 | F20: ='Task Agreement Form'!$E134 -> 0 | H20: =IF(F20>0,F20+($F$148/$G$8),F20) -> 0
... B48: ='Task Agreement Form'!$B162 -> 0 | E48: ='Task Agreement Form'!C162 -> 0 | F48: ='Task Agreement Form'!$E162 -> 0 | H48: =IF(F48>0,F48+($F$148/$G$8),F48) -> 0
B49: ='Task Agreement Form'!$B164 -> 0 | E49: ='Task Agreement Form'!C164 -> 0 | F49: ='Task Agreement Form'!$E164 -> 0 | H49: =IF(F49>0,F49+($F$148/$G$8),F49) -> 0
B50: ='Task Agreement Form'!$B165 -> 0 | E50: ='Task Agreement Form'!C165 -> 0 | F50: ='Task Agreement Form'!$E165 -> 0 | H50: =IF(F50>0,F50+($F$148/$G$8),F50) -> 0
B51: ='Task Agreement Form'!$B166 -> 0 | E51: ='Task Agreement Form'!C166 -> 0 | F51: ='Task Agreement Form'!$E166 -> 0 | H51: =IF(F51>0,F51+($F$148/$G$8),F51) -> 0
B52: ='Task Agreement Form'!$B167 -> 0 | E52: ='Task Agreement Form'!C167 -> 0 | F52: ='Task Agreement Form'!$E167 -> 0 | H52: =IF(F52>0,F52+($F$148/$G$8),F52) -> 0
B53: ='Task Agreement Form'!$B168 -> 0 | E53: ='Task Agreement Form'!C168 -> 0 | F53: ='Task Agreement Form'!$E168 -> 0 | H53: =IF(F53>0,F53+($F$148/$G$8),F53) -> 0
B54: ='Task Agreement Form'!$B169 -> 0 | E54: ='Task Agreement Form'!C169 -> 0 | F54: ='Task Agreement Form'!$E169 -> 0 | H54: =IF(F54>0,F54+($F$148/$G$8),F54) -> 0
B55: ='Task Agreement Form'!$B170 -> 0 | E55: ='Task Agreement Form'!C170 -> 0 | F55: ='Task Agreement Form'!$E170 -> 0 | H55: =IF(F55>0,F55+($F$148/$G$8),F55) -> 0
B56: ='Task Agreement Form'!$B171 -> 0 | E56: ='Task Agreement Form'!C171 -> 0 | F56: ='Task Agreement Form'!$E171 -> 0 | H56: =IF(F56>0,F56+($F$148/$G$8),F56) -> 0
B57: ='Task Agreement Form'!$B172 -> 0 | E57: ='Task Agreement Form'!C172 -> 0 | F57: ='Task Agreement Form'!$E172 -> 0 | H57: =IF(F57>0,F57+($F$148/$G$8),F57) -> 0
B58: ='Task Agreement Form'!$B173 -> 0 | E58: ='Task Agreement Form'!C173 -> 0 | F58: ='Task Agreement Form'!$E173 -> 0 | H58: =IF(F58>0,F58+($F$148/$G$8),F58) -> 0
B59: ='Task Agreement Form'!$B174 -> 0 | E59: ='Task Agreement Form'!C174 -> 0 | F59: ='Task Agreement Form'!$E174 -> 0 | H59: =IF(F59>0,F59+($F$148/$G$8),F59) -> 0
B60: ='Task Agreement Form'!$B175 -> 0 | E60: ='Task Agreement Form'!C175 -> 0 | F60: ='Task Agreement Form'!$E175 -> 0 | H60: =IF(F60>0,F60+($F$148/$G$8),F60) -> 0
... B62: ='Task Agreement Form'!$B177 -> 0 | E62: ='Task Agreement Form'!C177 -> 0 | F62: ='Task Agreement Form'!$E177 -> 0 | H62: =IF(F62>0,F62+($F$148/$G$8),F62) -> 0
B63: ='Task Agreement Form'!$B179 -> 0 | E63: ='Task Agreement Form'!C179 -> 0 | F63: ='Task Agreement Form'!$E179 -> 0 | H63: =IF(F63>0,F63+($F$148/$G$8),F63) -> 0
B64: ='Task Agreement Form'!$B180 -> 0 | E64: ='Task Agreement Form'!C180 -> 0 | F64: ='Task Agreement Form'!$E180 -> 0 | H64: =IF(F64>0,F64+($F$148/$G$8),F64) -> 0
B65: ='Task Agreement Form'!$B181 -> 0 | E65: ='Task Agreement Form'!C181 -> 0 | F65: ='Task Agreement Form'!$E181 -> 0 | H65: =IF(F65>0,F65+($F$148/$G$8),F65) -> 0
B66: ='Task Agreement Form'!$B182 -> 0 | E66: ='Task Agreement Form'!C182 -> 0 | F66: ='Task Agreement Form'!$E182 -> 0 | H66: =IF(F66>0,F66+($F$148/$G$8),F66) -> 0
B67: ='Task Agreement Form'!$B183 -> 0 | E67: ='Task Agreement Form'!C183 -> 0 | F67: ='Task Agreement Form'!$E183 -> 0 | H67: =IF(F67>0,F67+($F$148/$G$8),F67) -> 0
B68: ='Task Agreement Form'!$B184 -> 0 | E68: ='Task Agreement Form'!C184 -> 0 | F68: ='Task Agreement Form'!$E184 -> 0 | H68: =IF(F68>0,F68+($F$148/$G$8),F68) -> 0
B69: ='Task Agreement Form'!$B185 -> 0 | E69: ='Task Agreement Form'!C185 -> 0 | F69: ='Task Agreement Form'!$E185 -> 0 | H69: =IF(F69>0,F69+($F$148/$G$8),F69) -> 0
...
